[2024-06-24T15:09:13.810+0000] {taskinstance.py:1125} INFO - Dependencies all met for dep_context=non-requeueable deps ti=<TaskInstance: Assignment3.clean_the_data scheduled__2024-06-23T00:00:00+00:00 [queued]>
[2024-06-24T15:09:13.815+0000] {taskinstance.py:1125} INFO - Dependencies all met for dep_context=requeueable deps ti=<TaskInstance: Assignment3.clean_the_data scheduled__2024-06-23T00:00:00+00:00 [queued]>
[2024-06-24T15:09:13.815+0000] {taskinstance.py:1331} INFO - Starting attempt 1 of 2
[2024-06-24T15:09:13.821+0000] {taskinstance.py:1350} INFO - Executing <Task(PythonOperator): clean_the_data> on 2024-06-23 00:00:00+00:00
[2024-06-24T15:09:13.823+0000] {standard_task_runner.py:57} INFO - Started process 91 to run task
[2024-06-24T15:09:13.826+0000] {standard_task_runner.py:84} INFO - Running: ['***', 'tasks', 'run', 'Assignment3', 'clean_the_data', 'scheduled__2024-06-23T00:00:00+00:00', '--job-id', '8', '--raw', '--subdir', 'DAGS_FOLDER/assignment3_bigdata.py', '--cfg-path', '/tmp/tmpo7fpqmgx']
[2024-06-24T15:09:13.826+0000] {standard_task_runner.py:85} INFO - Job 8: Subtask clean_the_data
[2024-06-24T15:09:13.852+0000] {task_command.py:410} INFO - Running <TaskInstance: Assignment3.clean_the_data scheduled__2024-06-23T00:00:00+00:00 [running]> on host 183246c8fda6
[2024-06-24T15:09:13.886+0000] {taskinstance.py:1570} INFO - Exporting env vars: AIRFLOW_CTX_DAG_EMAIL='jaumesanchez1@gmail.com' AIRFLOW_CTX_DAG_OWNER='David' AIRFLOW_CTX_DAG_ID='Assignment3' AIRFLOW_CTX_TASK_ID='clean_the_data' AIRFLOW_CTX_EXECUTION_DATE='2024-06-23T00:00:00+00:00' AIRFLOW_CTX_TRY_NUMBER='1' AIRFLOW_CTX_DAG_RUN_ID='scheduled__2024-06-23T00:00:00+00:00'
[2024-06-24T15:09:13.891+0000] {taskinstance.py:1847} ERROR - Task failed with exception
Traceback (most recent call last):
  File "/home/airflow/.local/lib/python3.7/site-packages/airflow/operators/python.py", line 181, in execute
    return_value = self.execute_callable()
  File "/home/airflow/.local/lib/python3.7/site-packages/airflow/operators/python.py", line 198, in execute_callable
    return self.python_callable(*self.op_args, **self.op_kwargs)
  File "/opt/airflow/dags/assignment3_bigdata.py", line 38, in clean_the_data
    df = pd.read_csv(file_path)
  File "/home/airflow/.local/lib/python3.7/site-packages/pandas/util/_decorators.py", line 311, in wrapper
    return func(*args, **kwargs)
  File "/home/airflow/.local/lib/python3.7/site-packages/pandas/io/parsers/readers.py", line 586, in read_csv
    return _read(filepath_or_buffer, kwds)
  File "/home/airflow/.local/lib/python3.7/site-packages/pandas/io/parsers/readers.py", line 482, in _read
    parser = TextFileReader(filepath_or_buffer, **kwds)
  File "/home/airflow/.local/lib/python3.7/site-packages/pandas/io/parsers/readers.py", line 811, in __init__
    self._engine = self._make_engine(self.engine)
  File "/home/airflow/.local/lib/python3.7/site-packages/pandas/io/parsers/readers.py", line 1040, in _make_engine
    return mapping[engine](self.f, **self.options)  # type: ignore[call-arg]
  File "/home/airflow/.local/lib/python3.7/site-packages/pandas/io/parsers/c_parser_wrapper.py", line 51, in __init__
    self._open_handles(src, kwds)
  File "/home/airflow/.local/lib/python3.7/site-packages/pandas/io/parsers/base_parser.py", line 229, in _open_handles
    errors=kwds.get("encoding_errors", "strict"),
  File "/home/airflow/.local/lib/python3.7/site-packages/pandas/io/common.py", line 614, in get_handle
    storage_options=storage_options,
  File "/home/airflow/.local/lib/python3.7/site-packages/pandas/io/common.py", line 396, in _get_filepath_or_buffer
    raise ValueError(msg)
ValueError: Invalid file path or buffer object type: <class 'NoneType'>
[2024-06-24T15:09:13.896+0000] {taskinstance.py:1373} INFO - Marking task as UP_FOR_RETRY. dag_id=Assignment3, task_id=clean_the_data, execution_date=20240623T000000, start_date=20240624T150913, end_date=20240624T150913
[2024-06-24T15:09:13.901+0000] {standard_task_runner.py:109} ERROR - Failed to execute job 8 for task clean_the_data (Invalid file path or buffer object type: <class 'NoneType'>; 91)
[2024-06-24T15:09:13.924+0000] {local_task_job_runner.py:232} INFO - Task exited with return code 1
[2024-06-24T15:09:13.937+0000] {taskinstance.py:2674} INFO - 0 downstream tasks scheduled from follow-on schedule check
